[2025-02-23T20:15:09.283+0530] {taskinstance.py:1159} INFO - Dependencies all met for dep_context=non-requeueable deps ti=<TaskInstance: data_pipeline_dag.extract_data manual__2025-02-23T14:40:04.230842+00:00 [queued]>
[2025-02-23T20:15:09.286+0530] {taskinstance.py:1159} INFO - Dependencies all met for dep_context=requeueable deps ti=<TaskInstance: data_pipeline_dag.extract_data manual__2025-02-23T14:40:04.230842+00:00 [queued]>
[2025-02-23T20:15:09.286+0530] {taskinstance.py:1361} INFO - Starting attempt 2 of 2
[2025-02-23T20:15:09.290+0530] {taskinstance.py:1382} INFO - Executing <Task(PythonOperator): extract_data> on 2025-02-23 14:40:04.230842+00:00
[2025-02-23T20:15:09.293+0530] {standard_task_runner.py:57} INFO - Started process 13628 to run task
[2025-02-23T20:15:09.296+0530] {standard_task_runner.py:84} INFO - Running: ['airflow', 'tasks', 'run', 'data_pipeline_dag', 'extract_data', 'manual__2025-02-23T14:40:04.230842+00:00', '--job-id', '12', '--raw', '--subdir', 'DAGS_FOLDER/data_pipeline_dag.py', '--cfg-path', '/var/folders/kz/_l5jq2xx6db29k_3xyv2j8n40000gp/T/tmpf0uqh1us']
[2025-02-23T20:15:09.297+0530] {standard_task_runner.py:85} INFO - Job 12: Subtask extract_data
[2025-02-23T20:15:09.317+0530] {task_command.py:416} INFO - Running <TaskInstance: data_pipeline_dag.extract_data manual__2025-02-23T14:40:04.230842+00:00 [running]> on host ninja-its-macbook-air-90.local
[2025-02-23T20:15:09.337+0530] {taskinstance.py:1662} INFO - Exporting env vars: AIRFLOW_CTX_DAG_OWNER='airflow' AIRFLOW_CTX_DAG_ID='data_pipeline_dag' AIRFLOW_CTX_TASK_ID='extract_data' AIRFLOW_CTX_EXECUTION_DATE='2025-02-23T14:40:04.230842+00:00' AIRFLOW_CTX_TRY_NUMBER='2' AIRFLOW_CTX_DAG_RUN_ID='manual__2025-02-23T14:40:04.230842+00:00'
[2025-02-23T20:15:09.337+0530] {data_pipeline_dag.py:172} INFO - Received file path: None
[2025-02-23T20:15:09.338+0530] {data_pipeline_dag.py:174} ERROR - Invalid or missing file path: None
[2025-02-23T20:15:09.338+0530] {taskinstance.py:1937} ERROR - Task failed with exception
Traceback (most recent call last):
  File "/Users/nc25577_suryateja/Documents/air_pro/venv/lib/python3.9/site-packages/airflow/operators/python.py", line 192, in execute
    return_value = self.execute_callable()
  File "/Users/nc25577_suryateja/Documents/air_pro/venv/lib/python3.9/site-packages/airflow/operators/python.py", line 209, in execute_callable
    return self.python_callable(*self.op_args, **self.op_kwargs)
  File "/Users/nc25577_suryateja/Documents/air_pro/airflow/dags/data_pipeline_dag.py", line 175, in extract_and_convert
    raise ValueError(f"Invalid or missing file path: {file_path}")
ValueError: Invalid or missing file path: None
[2025-02-23T20:15:09.347+0530] {taskinstance.py:1400} INFO - Marking task as FAILED. dag_id=data_pipeline_dag, task_id=extract_data, execution_date=20250223T144004, start_date=20250223T144509, end_date=20250223T144509
[2025-02-23T20:15:09.350+0530] {standard_task_runner.py:104} ERROR - Failed to execute job 12 for task extract_data (Invalid or missing file path: None; 13628)
[2025-02-23T20:15:09.392+0530] {local_task_job_runner.py:228} INFO - Task exited with return code 1
[2025-02-23T20:15:09.400+0530] {taskinstance.py:2778} INFO - 0 downstream tasks scheduled from follow-on schedule check
