[2025-02-24T11:20:28.006+0530] {taskinstance.py:1159} INFO - Dependencies all met for dep_context=non-requeueable deps ti=<TaskInstance: fraud_detection_processing_dag.process_input_file manual__2025-02-24T05:35:11.806439+00:00 [queued]>
[2025-02-24T11:20:28.008+0530] {taskinstance.py:1159} INFO - Dependencies all met for dep_context=requeueable deps ti=<TaskInstance: fraud_detection_processing_dag.process_input_file manual__2025-02-24T05:35:11.806439+00:00 [queued]>
[2025-02-24T11:20:28.008+0530] {taskinstance.py:1361} INFO - Starting attempt 2 of 4
[2025-02-24T11:20:28.013+0530] {taskinstance.py:1382} INFO - Executing <Task(PythonOperator): process_input_file> on 2025-02-24 05:35:11.806439+00:00
[2025-02-24T11:20:28.017+0530] {standard_task_runner.py:57} INFO - Started process 10058 to run task
[2025-02-24T11:20:28.020+0530] {standard_task_runner.py:84} INFO - Running: ['airflow', 'tasks', 'run', 'fraud_detection_processing_dag', 'process_input_file', 'manual__2025-02-24T05:35:11.806439+00:00', '--job-id', '89', '--raw', '--subdir', 'DAGS_FOLDER/data_pipeline_dag.py', '--cfg-path', '/var/folders/kz/_l5jq2xx6db29k_3xyv2j8n40000gp/T/tmp4gwkicdo']
[2025-02-24T11:20:28.021+0530] {standard_task_runner.py:85} INFO - Job 89: Subtask process_input_file
[2025-02-24T11:20:28.040+0530] {task_command.py:416} INFO - Running <TaskInstance: fraud_detection_processing_dag.process_input_file manual__2025-02-24T05:35:11.806439+00:00 [running]> on host ninja-its-macbook-air-90.local
[2025-02-24T11:20:28.120+0530] {taskinstance.py:1662} INFO - Exporting env vars: AIRFLOW_CTX_DAG_OWNER='airflow' AIRFLOW_CTX_DAG_ID='fraud_detection_processing_dag' AIRFLOW_CTX_TASK_ID='process_input_file' AIRFLOW_CTX_EXECUTION_DATE='2025-02-24T05:35:11.806439+00:00' AIRFLOW_CTX_TRY_NUMBER='2' AIRFLOW_CTX_DAG_RUN_ID='manual__2025-02-24T05:35:11.806439+00:00'
[2025-02-24T11:20:28.120+0530] {configuration.py:1050} WARNING - section/key [file_path//users/nc25577_suryateja/documents/air_pro/input_files/uploaded_file] not found in config
[2025-02-24T11:20:28.122+0530] {taskinstance.py:1937} ERROR - Task failed with exception
Traceback (most recent call last):
  File "/Users/nc25577_suryateja/Documents/air_pro/venv/lib/python3.9/site-packages/airflow/operators/python.py", line 192, in execute
    return_value = self.execute_callable()
  File "/Users/nc25577_suryateja/Documents/air_pro/venv/lib/python3.9/site-packages/airflow/operators/python.py", line 209, in execute_callable
    return self.python_callable(*self.op_args, **self.op_kwargs)
  File "/Users/nc25577_suryateja/Documents/air_pro/airflow/dags/data_pipeline_dag.py", line 49, in process_input_file
    file_path = kwargs.get('conf', {}).get('file_path', os.path.join(TEMP_DIR, "uploaded_file"))
  File "/Users/nc25577_suryateja/Documents/air_pro/venv/lib/python3.9/site-packages/airflow/configuration.py", line 1052, in get
    raise AirflowConfigException(f"section/key [{section}/{key}] not found in config")
airflow.exceptions.AirflowConfigException: section/key [file_path//users/nc25577_suryateja/documents/air_pro/input_files/uploaded_file] not found in config
[2025-02-24T11:20:28.129+0530] {taskinstance.py:1400} INFO - Marking task as UP_FOR_RETRY. dag_id=fraud_detection_processing_dag, task_id=process_input_file, execution_date=20250224T053511, start_date=20250224T055028, end_date=20250224T055028
[2025-02-24T11:20:28.132+0530] {standard_task_runner.py:104} ERROR - Failed to execute job 89 for task process_input_file (section/key [file_path//users/nc25577_suryateja/documents/air_pro/input_files/uploaded_file] not found in config; 10058)
[2025-02-24T11:20:28.156+0530] {local_task_job_runner.py:228} INFO - Task exited with return code 1
[2025-02-24T11:20:28.165+0530] {taskinstance.py:2778} INFO - 0 downstream tasks scheduled from follow-on schedule check
