[2025-02-25T22:16:04.487+0530] {taskinstance.py:1159} INFO - Dependencies all met for dep_context=non-requeueable deps ti=<TaskInstance: fraud_detection_processing_dag.load_resources manual__2025-02-25T16:46:02.555343+00:00 [queued]>
[2025-02-25T22:16:04.489+0530] {taskinstance.py:1159} INFO - Dependencies all met for dep_context=requeueable deps ti=<TaskInstance: fraud_detection_processing_dag.load_resources manual__2025-02-25T16:46:02.555343+00:00 [queued]>
[2025-02-25T22:16:04.489+0530] {taskinstance.py:1361} INFO - Starting attempt 1 of 4
[2025-02-25T22:16:04.493+0530] {taskinstance.py:1382} INFO - Executing <Task(PythonOperator): load_resources> on 2025-02-25 16:46:02.555343+00:00
[2025-02-25T22:16:04.497+0530] {standard_task_runner.py:57} INFO - Started process 87034 to run task
[2025-02-25T22:16:04.500+0530] {standard_task_runner.py:84} INFO - Running: ['airflow', 'tasks', 'run', 'fraud_detection_processing_dag', 'load_resources', 'manual__2025-02-25T16:46:02.555343+00:00', '--job-id', '373', '--raw', '--subdir', 'DAGS_FOLDER/data_pipeline_dag.py', '--cfg-path', '/var/folders/kz/_l5jq2xx6db29k_3xyv2j8n40000gp/T/tmpeiw3m_vw']
[2025-02-25T22:16:04.501+0530] {standard_task_runner.py:85} INFO - Job 373: Subtask load_resources
[2025-02-25T22:16:04.523+0530] {task_command.py:416} INFO - Running <TaskInstance: fraud_detection_processing_dag.load_resources manual__2025-02-25T16:46:02.555343+00:00 [running]> on host ninja-its-macbook-air-90.local
[2025-02-25T22:16:04.545+0530] {taskinstance.py:1662} INFO - Exporting env vars: AIRFLOW_CTX_DAG_OWNER='airflow' AIRFLOW_CTX_DAG_ID='fraud_detection_processing_dag' AIRFLOW_CTX_TASK_ID='load_resources' AIRFLOW_CTX_EXECUTION_DATE='2025-02-25T16:46:02.555343+00:00' AIRFLOW_CTX_TRY_NUMBER='1' AIRFLOW_CTX_DAG_RUN_ID='manual__2025-02-25T16:46:02.555343+00:00'
[2025-02-25T22:16:04.546+0530] {data_pipeline_dag.py:31} INFO - Loading model and scaler...
[2025-02-25T22:16:04.547+0530] {data_pipeline_dag.py:43} ERROR - Failed to load resources: name 'pickle' is not defined
[2025-02-25T22:16:04.547+0530] {taskinstance.py:1937} ERROR - Task failed with exception
Traceback (most recent call last):
  File "/Users/nc25577_suryateja/Documents/air_pro/venv/lib/python3.9/site-packages/airflow/operators/python.py", line 192, in execute
    return_value = self.execute_callable()
  File "/Users/nc25577_suryateja/Documents/air_pro/venv/lib/python3.9/site-packages/airflow/operators/python.py", line 209, in execute_callable
    return self.python_callable(*self.op_args, **self.op_kwargs)
  File "/Users/nc25577_suryateja/Documents/air_pro/airflow/dags/data_pipeline_dag.py", line 38, in load_resources
    model = pickle.load(model_file)
NameError: name 'pickle' is not defined
[2025-02-25T22:16:04.560+0530] {taskinstance.py:1400} INFO - Marking task as UP_FOR_RETRY. dag_id=fraud_detection_processing_dag, task_id=load_resources, execution_date=20250225T164602, start_date=20250225T164604, end_date=20250225T164604
[2025-02-25T22:16:04.564+0530] {standard_task_runner.py:104} ERROR - Failed to execute job 373 for task load_resources (name 'pickle' is not defined; 87034)
[2025-02-25T22:16:04.595+0530] {local_task_job_runner.py:228} INFO - Task exited with return code 1
[2025-02-25T22:16:04.606+0530] {taskinstance.py:2778} INFO - 0 downstream tasks scheduled from follow-on schedule check
