[2025-02-24T11:33:24.138+0530] {taskinstance.py:1149} INFO - Dependencies not met for <TaskInstance: fraud_detection_processing_dag.engineer_features manual__2025-02-24T05:35:11.806439+00:00 [up_for_retry]>, dependency 'Not In Retry Period' FAILED: Task is not ready for retry yet but will be retried automatically. Current date is 2025-02-24T06:03:24.138479+00:00 and task will be retried at 2025-02-24T06:08:22.665139+00:00.
[2025-02-24T11:33:24.138+0530] {local_task_job_runner.py:154} INFO - Task is not able to be run
[2025-02-24T11:38:25.546+0530] {taskinstance.py:1159} INFO - Dependencies all met for dep_context=non-requeueable deps ti=<TaskInstance: fraud_detection_processing_dag.engineer_features manual__2025-02-24T05:35:11.806439+00:00 [queued]>
[2025-02-24T11:38:25.549+0530] {taskinstance.py:1159} INFO - Dependencies all met for dep_context=requeueable deps ti=<TaskInstance: fraud_detection_processing_dag.engineer_features manual__2025-02-24T05:35:11.806439+00:00 [queued]>
[2025-02-24T11:38:25.549+0530] {taskinstance.py:1361} INFO - Starting attempt 2 of 4
[2025-02-24T11:38:25.554+0530] {taskinstance.py:1382} INFO - Executing <Task(PythonOperator): engineer_features> on 2025-02-24 05:35:11.806439+00:00
[2025-02-24T11:38:25.558+0530] {standard_task_runner.py:57} INFO - Started process 12162 to run task
[2025-02-24T11:38:25.560+0530] {standard_task_runner.py:84} INFO - Running: ['airflow', 'tasks', 'run', 'fraud_detection_processing_dag', 'engineer_features', 'manual__2025-02-24T05:35:11.806439+00:00', '--job-id', '111', '--raw', '--subdir', 'DAGS_FOLDER/data_pipeline_dag.py', '--cfg-path', '/var/folders/kz/_l5jq2xx6db29k_3xyv2j8n40000gp/T/tmpf3yo2k73']
[2025-02-24T11:38:25.562+0530] {standard_task_runner.py:85} INFO - Job 111: Subtask engineer_features
[2025-02-24T11:38:25.581+0530] {task_command.py:416} INFO - Running <TaskInstance: fraud_detection_processing_dag.engineer_features manual__2025-02-24T05:35:11.806439+00:00 [running]> on host ninja-its-macbook-air-90.local
[2025-02-24T11:38:25.661+0530] {taskinstance.py:1662} INFO - Exporting env vars: AIRFLOW_CTX_DAG_OWNER='airflow' AIRFLOW_CTX_DAG_ID='fraud_detection_processing_dag' AIRFLOW_CTX_TASK_ID='engineer_features' AIRFLOW_CTX_EXECUTION_DATE='2025-02-24T05:35:11.806439+00:00' AIRFLOW_CTX_TRY_NUMBER='2' AIRFLOW_CTX_DAG_RUN_ID='manual__2025-02-24T05:35:11.806439+00:00'
[2025-02-24T11:38:25.661+0530] {data_pipeline_dag.py:153} INFO - Engineering features...
[2025-02-24T11:38:25.663+0530] {data_pipeline_dag.py:182} ERROR - Error in feature engineering: Processed data file not found at /Users/nc25577_suryateja/Documents/air_pro/input_files/processed_df.csv
[2025-02-24T11:38:25.663+0530] {taskinstance.py:1937} ERROR - Task failed with exception
Traceback (most recent call last):
  File "/Users/nc25577_suryateja/Documents/air_pro/venv/lib/python3.9/site-packages/airflow/operators/python.py", line 192, in execute
    return_value = self.execute_callable()
  File "/Users/nc25577_suryateja/Documents/air_pro/venv/lib/python3.9/site-packages/airflow/operators/python.py", line 209, in execute_callable
    return self.python_callable(*self.op_args, **self.op_kwargs)
  File "/Users/nc25577_suryateja/Documents/air_pro/airflow/dags/data_pipeline_dag.py", line 157, in engineer_features
    raise FileNotFoundError(f"Processed data file not found at {input_path}")
FileNotFoundError: Processed data file not found at /Users/nc25577_suryateja/Documents/air_pro/input_files/processed_df.csv
[2025-02-24T11:38:25.670+0530] {taskinstance.py:1400} INFO - Marking task as UP_FOR_RETRY. dag_id=fraud_detection_processing_dag, task_id=engineer_features, execution_date=20250224T053511, start_date=20250224T060825, end_date=20250224T060825
[2025-02-24T11:38:25.673+0530] {standard_task_runner.py:104} ERROR - Failed to execute job 111 for task engineer_features (Processed data file not found at /Users/nc25577_suryateja/Documents/air_pro/input_files/processed_df.csv; 12162)
[2025-02-24T11:38:25.697+0530] {local_task_job_runner.py:228} INFO - Task exited with return code 1
[2025-02-24T11:38:25.706+0530] {taskinstance.py:2778} INFO - 0 downstream tasks scheduled from follow-on schedule check
